Traceback (most recent call last):
  File "/usr/share/miniconda/envs/taxcalc-dev/lib/python3.11/site-packages/jupyter_cache/executors/utils.py", line 58, in single_nb_execution
    executenb(
  File "/usr/share/miniconda/envs/taxcalc-dev/lib/python3.11/site-packages/nbclient/client.py", line 1314, in execute
    return NotebookClient(nb=nb, resources=resources, km=km, **kwargs).execute()
           ^^^^^^^^^^^^^^^^^^^^^^^^^^^^^^^^^^^^^^^^^^^^^^^^^^^^^^^^^^^^^^^^^^^^^
  File "/usr/share/miniconda/envs/taxcalc-dev/lib/python3.11/site-packages/jupyter_core/utils/__init__.py", line 165, in wrapped
    return loop.run_until_complete(inner)
           ^^^^^^^^^^^^^^^^^^^^^^^^^^^^^^
  File "/usr/share/miniconda/envs/taxcalc-dev/lib/python3.11/asyncio/base_events.py", line 654, in run_until_complete
    return future.result()
           ^^^^^^^^^^^^^^^
  File "/usr/share/miniconda/envs/taxcalc-dev/lib/python3.11/site-packages/nbclient/client.py", line 709, in async_execute
    await self.async_execute_cell(
  File "/usr/share/miniconda/envs/taxcalc-dev/lib/python3.11/site-packages/nbclient/client.py", line 1062, in async_execute_cell
    await self._check_raise_for_error(cell, cell_index, exec_reply)
  File "/usr/share/miniconda/envs/taxcalc-dev/lib/python3.11/site-packages/nbclient/client.py", line 918, in _check_raise_for_error
    raise CellExecutionError.from_cell_and_msg(cell, exec_reply_content)
nbclient.exceptions.CellExecutionError: An error occurred while executing the following cell:
------------------
fig = calc1.pch_graph(calc2)
output_notebook()
show(fig)
------------------


[0;31m---------------------------------------------------------------------------[0m
[0;31mValueError[0m                                Traceback (most recent call last)
Cell [0;32mIn[12], line 3[0m
[1;32m      1[0m fig [38;5;241m=[39m calc1[38;5;241m.[39mpch_graph(calc2)
[1;32m      2[0m output_notebook()
[0;32m----> 3[0m [43mshow[49m[43m([49m[43mfig[49m[43m)[49m

File [0;32m/usr/share/miniconda/envs/taxcalc-dev/lib/python3.11/site-packages/bokeh/io/showing.py:160[0m, in [0;36mshow[0;34m(obj, browser, new, notebook_handle, notebook_url, **kwargs)[0m
[1;32m    157[0m     [38;5;28;01massert[39;00m state[38;5;241m.[39mnotebook_type [38;5;129;01mis[39;00m [38;5;129;01mnot[39;00m [38;5;28;01mNone[39;00m
[1;32m    158[0m     [38;5;28;01mreturn[39;00m run_notebook_hook(state[38;5;241m.[39mnotebook_type, [38;5;124m'[39m[38;5;124mapp[39m[38;5;124m'[39m, obj, state, notebook_url, [38;5;241m*[39m[38;5;241m*[39mkwargs)
[0;32m--> 160[0m [38;5;28;01mraise[39;00m [38;5;167;01mValueError[39;00m(_BAD_SHOW_MSG)

[0;31mValueError[0m: Invalid object to show. The object to passed to show must be one of:

* a UIElement (e.g. a plot, figure, widget or layout)
* a Bokeh Application
* a callable suitable to an application FunctionHandler


